Workbook

Sheet Build Status
A1: Akki OS — Build Status
A2: 20 September 2026 (refresh)
A4: 1 — What We're Building
A6: Component | B6: What it does | D6: Reqs
A7: Akki OS core | B7: Six engines (SyniSense, Solva, Northena, Mtafiti, Targeta, Mkondo) + the Watch + the Ledger — the governed platform. Docs 1–20 and extensions. | D7: 286
A8: Rules Service | B8: The Policy Administration Point — rule authoring, ceremony, adoption, the Registry. | D8: 27
A9: DAP | B9: External-party acquisition portal built on Akki — browse, connect, extract, fine-tune, download. | D9: 30
A10: Security hardening | B10: Assurance promises (Watch conduct) plus Trojan/whisper amendments (artefact and output-content threats). | D10: 35
A11: Governance Architecture | B11: The standard (Part 1) everything above is measured against, translated into per-component build targets (Part 2). | D11: 41
A12: Agent & Swarm Containment | B12: Contains a lab's own deployed agent(s) — capability ceilings, earned scope, coalition bounding. Governance model only; integration layer explicitly out of scope. | D12: 12
A14: Total, defined and buildable today | D14: 589
A15: Refreshed 18 Sep 2026: +47 (SEC, DET, FP, TD, HR, BC, DAP-37/38, serving integrity, watch learning, S-26–S-29). Previous baseline 431 / 444 rows.
A16: Refreshed 20 Sep 2026: +73 (ENT-1–49 entitlement; MEM-1–11 memory compaction; PRIN-1–13 principal model). Previous total 478.
A17: Refreshed 20 Sep 2026 (b): +31 (CON-1–31 content registry). Previous total 551.
A19: Gap | B19: State
A20: G-1 — No enumerated Trusted Computing Base | B20: OPEN
A21: G-2 — No architecture description | B21: OPEN
A22: G-3 — Asset inventory covers estate sources only | B22: PARTIAL — DAP-1/2 close it for external parties
A23: G-4 — No assessment procedure on any base rule | B23: OPEN
A24: G-5 — Checkpoint roles named only for the Watch | B24: PARTIAL — DAP §4 names them for every DAP operation
A25: G-6 — No security architecture description | B25: PARTIAL — Watch confirmed to meet all 3 reference-monitor properties; not yet written up
A26: G-7 — No named SFPs; lower-the-standard is subject-alterable | B26: OPEN — ruling pending (R-2)
A27: G-8 — Receipt omits identity, timestamp | B27: SPEC-CLOSED — Security_Promise_Set_Amendments Amendment 3. Not built.
A28: G-9 — No change-control procedure for system rules | B28: SPEC-CLOSED — Rules Service RBM-7/RBM-8. Not built.
A29: G-10 — No determinism inventory | B29: OPEN
A30: G-11 — No failure-type enumeration | B30: PARTIAL — DAP-28/29/30 specify it for DAP; not platform-wide
... A36: Rules Service implementation (builder's audit) | B36: Nothing built — spec complete, code not started
A39: 3 — Missing Requirements — Fully Open, No Spec Yet
A41: — TCB Enumeration — apply Attribute 1's test to every Doc 0 component, publish the list (closes G-1)
A42: — Security Architecture Description — ADV_ARC-style write-up for MOAC, distance gate, format gate (closes G-6 fully)
A43: — Named Security Function Policies + the lower-the-standard ruling (closes G-7)
A44: — Determinism Inventory — classify every component deterministic/learned in one place, map to EU AI Act Art. 14 (closes G-10)
A45: — Failure Posture Enumeration — platform-wide, not only DAP's slice (closes G-11 fully)
A46: — Trust Domain Description + deployment-model ruling, general case (closes G-12 fully)
A47: — Hand-off Generalisation spec for Mkondo (closes G-13)
A48: — Business Continuity Annex
A49: — Pruning & Unlearning Amendment (DAP-37/38, S-26)
A52: 4 — Generate Next
A54: Say which, and it's the next document built. Recommended first: TCB Enumeration + Security Architecture Description — both foundational, both referenced by other open gaps (G-2, G-5, G-6, G-10 all depend on one or both existing first).
A56: Full requirement-level detail, every ID, every citation: the System Rules Registry sheet.

Sheet Audit Summary
A1: Akki OS — Audit Summary
A2: Every figure is a formula over QA Verification and Check Register. Nothing is entered here.
A4: Rule verdicts by weight | B4: COUNTS | C4: UNRATIFIED | D4: OPEN | E4: UNDEFINED | F4: All
A5: PASS | B5: =COUNTIFS('QA Verification'!$H$2:$H$603,$A5,'QA Verification'!$L$2:$L$603,B$4) | C5: =COUNTIFS('QA Verification'!$H$2:$H$603,$A5,'QA Verification'!$L$2:$L$603,C$4) | D5: =COUNTIFS('QA Verification'!$H$2:$H$603,$A5,'QA Verification'!$L$2:$L$603,D$4) | E5: =COUNTIFS('QA Verification'!$H$2:$H$603,$A5,'QA Verification'!$L$2:$L$603,E$4) | F5: =SUM(B5:E5)
A6: FAIL | B6: =COUNTIFS('QA Verification'!$H$2:$H$603,$A6,'QA Verification'!$L$2:$L$603,B$4) | C6: =COUNTIFS('QA Verification'!$H$2:$H$603,$A6,'QA Verification'!$L$2:$L$603,C$4) | D6: =COUNTIFS('QA Verification'!$H$2:$H$603,$A6,'QA Verification'!$L$2:$L$603,D$4) | E6: =COUNTIFS('QA Verification'!$H$2:$H$603,$A6,'QA Verification'!$L$2:$L$603,E$4) | F6: =SUM(B6:E6)
A7: NOT BUILT | B7: =COUNTIFS('QA Verification'!$H$2:$H$603,$A7,'QA Verification'!$L$2:$L$603,B$4) | C7: =COUNTIFS('QA Verification'!$H$2:$H$603,$A7,'QA Verification'!$L$2:$L$603,C$4) | D7: =COUNTIFS('QA Verification'!$H$2:$H$603,$A7,'QA Verification'!$L$2:$L$603,D$4) | E7: =COUNTIFS('QA Verification'!$H$2:$H$603,$A7,'QA Verification'!$L$2:$L$603,E$4) | F7: =SUM(B7:E7)
A8: NOT VERIFIABLE | B8: =COUNTIFS('QA Verification'!$H$2:$H$603,$A8,'QA Verification'!$L$2:$L$603,B$4) | C8: =COUNTIFS('QA Verification'!$H$2:$H$603,$A8,'QA Verification'!$L$2:$L$603,C$4) | D8: =COUNTIFS('QA Verification'!$H$2:$H$603,$A8,'QA Verification'!$L$2:$L$603,D$4) | E8: =COUNTIFS('QA Verification'!$H$2:$H$603,$A8,'QA Verification'!$L$2:$L$603,E$4) | F8: =SUM(B8:E8)
A9: NOT EXAMINED | B9: =COUNTIFS('QA Verification'!$H$2:$H$603,$A9,'QA Verification'!$L$2:$L$603,B$4) | C9: =COUNTIFS('QA Verification'!$H$2:$H$603,$A9,'QA Verification'!$L$2:$L$603,C$4) | D9: =COUNTIFS('QA Verification'!$H$2:$H$603,$A9,'QA Verification'!$L$2:$L$603,D$4) | E9: =COUNTIFS('QA Verification'!$H$2:$H$603,$A9,'QA Verification'!$L$2:$L$603,E$4) | F9: =SUM(B9:E9)
A10: (no verdict yet) | B10: =COUNTIFS('QA Verification'!$H$2:$H$603,"",'QA Verification'!$L$2:$L$603,B$4) | C10: =COUNTIFS('QA Verification'!$H$2:$H$603,"",'QA Verification'!$L$2:$L$603,C$4) | D10: =COUNTIFS('QA Verification'!$H$2:$H$603,"",'QA Verification'!$L$2:$L$603,D$4) | E10: =COUNTIFS('QA Verification'!$H$2:$H$603,"",'QA Verification'!$L$2:$L$603,E$4) | F10: =SUM(B10:E10)
A11: Total | B11: =SUM(B5:B10) | C11: =SUM(C5:C10) | D11: =SUM(D5:D10) | E11: =SUM(E5:E10) | F11: =SUM(F5:F10)
A13: Examination load | B13: Rules
A14: Effective Tier A — examined in full | B14: =COUNTIF('QA Verification'!$R$2:$R$603,"A*")
A15: Effective Tier B — sampled ≥ 30% per document | B15: =COUNTIF('QA Verification'!$R$2:$R$603,"B*")
A16: Weight COUNTS held at V7 by the v1 heading derivation and not raised by §6 | B16: =COUNTIFS('QA Verification'!$L$2:$L$603,"COUNTS",'QA Verification'!$P$2:$P$603,"V7")
A17: Rows whose class is PROVISIONAL (derive from rule text before relying on it) | B17: =COUNTIF('QA Verification'!$Q$2:$Q$603,"*PROVISIONAL*")
A18: Rows with status UNDEFINED awaiting owner ruling | B18: =COUNTIF('QA Verification'!$K$2:$K$603,"UNDEFINED")
A19: FAIL by severity — S1 | B19: =COUNTIFS('QA Verification'!$H$2:$H$603,"FAIL",'QA Verification'!$T$2:$T$603,"S1")
A20: FAIL by severity — S2 | B20: =COUNTIFS('QA Verification'!$H$2:$H$603,"FAIL",'QA Verification'!$T$2:$T$603,"S2")
A21: FAIL by severity — S3 | B21: =COUNTIFS('QA Verification'!$H$2:$H$603,"FAIL",'QA Verification'!$T$2:$T$603,"S3")
A22: FAIL by severity — S4 | B22: =COUNTIFS('QA Verification'!$H$2:$H$603,"FAIL",'QA Verification'!$T$2:$T$603,"S4")
A23: FAIL recorded without a severity (record defect) | B23: =COUNTIFS('QA Verification'!$H$2:$H$603,"FAIL",'QA Verification'!$T$2:$T$603,"")
A24: NOT EXAMINED recorded without a reason (record defect) | B24: =COUNTIFS('QA Verification'!$H$2:$H$603,"NOT EXAMINED",'QA Verification'!$W$2:$W$603,"")
A26: Check Register | B26: Count
A27: PASS | B27: =COUNTIF('Check Register'!$J$2:$J$181,A27)
A28: FAIL | B28: =COUNTIF('Check Register'!$J$2:$J$181,A28)
A29: NOT BUILT | B29: =COUNTIF('Check Register'!$J$2:$J$181,A29)
A30: NOT VERIFIABLE | B30: =COUNTIF('Check Register'!$J$2:$J$181,A30)
A31: SOUND | B31: =COUNTIF('Check Register'!$J$2:$J$181,A31)
A32: DEFECT | B32: =COUNTIF('Check Register'!$J$2:$J$181,A32)
A33: NOT ASSESSABLE | B33: =COUNTIF('Check Register'!$J$2:$J$181,A33)
A34: (no verdict yet) | B34: =COUNTBLANK('Check Register'!$J$2:$J$181)

Sheet QA Verification
A1: Rule ID | B1: Doc | C1: Status | D1: Primary verification class | E1: Secondary class | F1: Evidence required (primary) | G1: Sampling tier | H1: Auditor verdict | I1: Evidence examined (ref) | J1: Finding ref | K1: Normalised status | L1: Weight | M1: Statement basis | N1: §6 check ID(s) | O1: §6 class(es) — governs | P1: Effective class | Q1: Class basis | R1: Effective tier | S1: Observed (stated without evaluation) | T1: Severity (FAIL only) | U1: Commit · ratchet | V1: Rule-text quality (Part 0) | W1: NOT EXAMINED reason | X1: Reviewer re-performance
A2: A5.1 | B2: Doc 1 | C2: CANON | D2: V7 — Document & design inspection | F2: Specification text against implementation description; provenance sections; objective card lines | G2: A — 100% | K2: =IFERROR(INDEX('Status Map'!$B$2:$B$12,MATCH(C2,'Status Map'!$A$2:$A$12,0)),"UNDEFINED") | L2: =IFERROR(INDEX('Status Map'!$C$2:$C$12,MATCH(C2,'Status Map'!$A$2:$A$12,0)),"UNDEFINED") | M2: HEADING ONLY | N2: C-6.3.1 | O2: V2 | P2: =IF(O2<>"",O2,LEFT(D2,2)) | Q2: =IF(O2<>"","Standards §6",IF(M2="HEADING ONLY","Derived from heading — PROVISIONAL",IF(M2="TEXT NOT IN REGISTRY","No text to derive from — PROVISIONAL","Derived from registered statement"))) | R2: =IF(OR(LEFT(G2,1)="A",L2="COUNTS",ISNUMBER(SEARCH("V1",P2)),ISNUMBER(SEARCH("V2",P2)),ISNUMBER(SEARCH("V5",P2))),"A — 100%","B — sample ≥ 30%")
A3: A5.2 | B3: Doc 1 | C3: CANON | D3: V7 — Document & design inspection | F3: Specification text against implementation description; provenance sections; objective card lines | G3: A — 100% | K3: =IFERROR(INDEX('Status Map'!$B$2:$B$12,MATCH(C3,'Status Map'!$A$2:$A$12,0)),"UNDEFINED") | L3: =IFERROR(INDEX('Status Map'!$C$2:$C$12,MATCH(C3,'Status Map'!$A$2:$A$12,0)),"UNDEFINED") | M3: HEADING ONLY | P3: =IF(O3<>"",O3,LEFT(D3,2)) | Q3: =IF(O3<>"","Standards §6",IF(M3="HEADING ONLY","Derived from heading — PROVISIONAL",IF(M3="TEXT NOT IN REGISTRY","No text to derive from — PROVISIONAL","Derived from registered statement"))) | R3: =IF(OR(LEFT(G3,1)="A",L3="COUNTS",ISNUMBER(SEARCH("V1",P3)),ISNUMBER(SEARCH("V2",P3)),ISNUMBER(SEARCH("V5",P3))),"A — 100%","B — sample ≥ 30%")
A4: A5.3 | B4: Doc 1 | C4: CANON | D4: V7 — Document & design inspection | F4: Specification text against implementation description; provenance sections; objective card lines | G4: A — 100% | K4: =IFERROR(INDEX('Status Map'!$B$2:$B$12,MATCH(C4,'Status Map'!$A$2:$A$12,0)),"UNDEFINED") | L4: =IFERROR(INDEX('Status Map'!$C$2:$C$12,MATCH(C4,'Status Map'!$A$2:$A$12,0)),"UNDEFINED") | M4: HEADING ONLY | P4: =IF(O4<>"",O4,LEFT(D4,2)) | Q4: =IF(O4<>"","Standards §6",IF(M4="HEADING ONLY","Derived from heading — PROVISIONAL",IF(M4="TEXT NOT IN REGISTRY","No text to derive from — PROVISIONAL","Derived from registered statement"))) | R4: =IF(OR(LEFT(G4,1)="A",L4="COUNTS",ISNUMBER(SEARCH("V1",P4)),ISNUMBER(SEARCH("V2",P4)),ISNUMBER(SEARCH("V5",P4))),"A — 100%","B — sample ≥ 30%")
A5: A5.4 | B5: Doc 1 | C5: CANON | D5: V7 — Document & design inspection | F5: Specification text against implementation description; provenance sections; objective card lines | G5: A — 100% | K5: =IFERROR(INDEX('Status Map'!$B$2:$B$12,MATCH(C5,'Status Map'!$A$2:$A$12,0)),"UNDEFINED") | L5: =IFERROR(INDEX('Status Map'!$C$2:$C$12,MATCH(C5,'Status Map'!$A$2:$A$12,0)),"UNDEFINED") | M5: HEADING ONLY | P5: =IF(O5<>"",O5,LEFT(D5,2)) | Q5: =IF(O5<>"","Standards §6",IF(M5="HEADING ONLY","Derived from heading — PROVISIONAL",IF(M5="TEXT NOT IN REGISTRY","No text to derive from — PROVISIONAL","Derived from registered statement"))) | R5: =IF(OR(LEFT(G5,1)="A",L5="COUNTS",ISNUMBER(SEARCH("V1",P5)),ISNUMBER(SEARCH("V2",P5)),ISNUMBER(SEARCH("V5",P5))),"A — 100%","B — sample ≥ 30%")
A6: A5.5 | B6: Doc 1 | C6: CANON | D6: V7 — Document & design inspection | F6: Specification text against implementation description; provenance sections; objective card lines | G6: A — 100% | K6: =IFERROR(INDEX('Status Map'!$B$2:$B$12,MATCH(C6,'Status Map'!$A$2:$A$12,0)),"UNDEFINED") | L6: =IFERROR(INDEX('Status Map'!$C$2:$C$12,MATCH(C6,'Status Map'!$A$2:$A$12,0)),"UNDEFINED") | M6: HEADING ONLY | P6: =IF(O6<>"",O6,LEFT(D6,2)) | Q6: =IF(O6<>"","Standards §6",IF(M6="HEADING ONLY","Derived from heading — PROVISIONAL",IF(M6="TEXT NOT IN REGISTRY","No text to derive from — PROVISIONAL","Derived from registered statement"))) | R6: =IF(OR(LEFT(G6,1)="A",L6="COUNTS",ISNUMBER(SEARCH("V1",P6)),ISNUMBER(SEARCH("V2",P6)),ISNUMBER(SEARCH("V5",P6))),"A — 100%","B — sample ≥ 30%")
A7: A5.6 | B7: Doc 1 | C7: CANON | D7: V7 — Document & design inspection | F7: Specification text against implementation description; provenance sections; objective card lines | G7: A — 100% | K7: =IFERROR(INDEX('Status Map'!$B$2:$B$12,MATCH(C7,'Status Map'!$A$2:$A$12,0)),"UNDEFINED") | L7: =IFERROR(INDEX('Status Map'!$C$2:$C$12,MATCH(C7,'Status Map'!$A$2:$A$12,0)),"UNDEFINED") | M7: HEADING ONLY | P7: =IF(O7<>"",O7,LEFT(D7,2)) | Q7: =IF(O7<>"","Standards §6",IF(M7="HEADING ONLY","Derived from heading — PROVISIONAL",IF(M7="TEXT NOT IN REGISTRY","No text to derive from — PROVISIONAL","Derived from registered statement"))) | R7: =IF(OR(LEFT(G7,1)="A",L7="COUNTS",ISNUMBER(SEARCH("V1",P7)),ISNUMBER(SEARCH("V2",P7)),ISNUMBER(SEARCH("V5",P7))),"A — 100%","B — sample ≥ 30%")
A8: A5.7 | B8: Doc 1 | C8: CANON | D8: V3 — Record evidence | F8: Ledger rows inspected; hash-chain verifier receipt; refused operations present on identical terms | G8: A — 100% | K8: =IFERROR(INDEX('Status Map'!$B$2:$B$12,MATCH(C8,'Status Map'!$A$2:$A$12,0)),"UNDEFINED") | L8: =IFERROR(INDEX('Status Map'!$C$2:$C$12,MATCH(C8,'Status Map'!$A$2:$A$12,0)),"UNDEFINED") | M8: HEADING ONLY | N8: C-6.3.6 | O8: V3 | P8: =IF(O8<>"",O8,LEFT(D8,2)) | Q8: =IF(O8<>"","Standards §6",IF(M8="HEADING ONLY","Derived from heading — PROVISIONAL",IF(M8="TEXT NOT IN REGISTRY","No text to derive from — PROVISIONAL","Derived from registered statement"))) | R8: =IF(OR(LEFT(G8,1)="A",L8="COUNTS",ISNUMBER(SEARCH("V1",P8)),ISNUMBER(SEARCH("V2",P8)),ISNUMBER(SEARCH("V5",P8))),"A — 100%","B — sample ≥ 30%")
A9: A5.8 | B9: Doc 1 | C9: CANON | D9: V3 — Record evidence | F9: Ledger rows inspected; hash-chain verifier receipt; refused operations present on identical terms | G9: A — 100% | K9: =IFERROR(INDEX('Status Map'!$B$2:$B$12,MATCH(C9,'Status Map'!$A$2:$A$12,0)),"UNDEFINED") | L9: =IFERROR(INDEX('Status Map'!$C$2:$C$12,MATCH(C9,'Status Map'!$A$2:$A$12,0)),"UNDEFINED") | M9: HEADING ONLY | P9: =IF(O9<>"",O9,LEFT(D9,2)) | Q9: =IF(O9<>"","Standards §6",IF(M9="HEADING ONLY","Derived from heading — PROVISIONAL",IF(M9="TEXT NOT IN REGISTRY","No text to derive from — PROVISIONAL","Derived from registered statement"))) | R9: =IF(OR(LEFT(G9,1)="A",L9="COUNTS",ISNUMBER(SEARCH("V1",P9)),ISNUMBER(SEARCH("V2",P9)),ISNUMBER(SEARCH("V5",P9))),"A — 100%","B — sample ≥ 30%")
A10: A5.9 | B10: Doc 1 | C10: CANON | D10: V5 — Failure-injection demonstration | F10: Dependency made unreachable or check made to error; observed refusal; no result returned; stale marker where degradation is the ruled posture | G10: A — 100% | K10: =IFERROR(INDEX('Status Map'!$B$2:$B$12,MATCH(C10,'Status Map'!$A$2:$A$12,0)),"UNDEFINED") | L10: =IFERROR(INDEX('Status Map'!$C$2:$C$12,MATCH(C10,'Status Map'!$A$2:$A$12,0)),"UNDEFINED") | M10: HEADING ONLY | P10: =IF(O10<>"",O10,LEFT(D10,2)) | Q10: =IF(O10<>"","Standards §6",IF(M10="HEADING ONLY","Derived from heading — PROVISIONAL",IF(M10="TEXT NOT IN REGISTRY","No text to derive from — PROVISIONAL","Derived from registered statement"))) | R10: =IF(OR(LEFT(G10,1)="A",L10="COUNTS",ISNUMBER(SEARCH("V1",P10)),ISNUMBER(SEARCH("V2",P10)),ISNUMBER(SEARCH("V5",P10))),"A — 100%","B — sample ≥ 30%")
A11: A5.1 | B11: Doc 2 | C11: CANON | D11: V7 — Document & design inspection | F11: Specification text against implementation description; provenance sections; objective card lines | G11: B — sample ≥ 30% | K11: =IFERROR(INDEX('Status Map'!$B$2:$B$12,MATCH(C11,'Status Map'!$A$2:$A$12,0)),"UNDEFINED") | L11: =IFERROR(INDEX('Status Map'!$C$2:$C$12,MATCH(C11,'Status Map'!$A$2:$A$12,0)),"UNDEFINED") | M11: HEADING ONLY | P11: =IF(O11<>"",O11,LEFT(D11,2)) | Q11: =IF(O11<>"","Standards §6",IF(M11="HEADING ONLY","Derived from heading — PROVISIONAL",IF(M11="TEXT NOT IN REGISTRY","No text to derive from — PROVISIONAL","Derived from registered statement"))) | R11: =IF(OR(LEFT(G11,1)="A",L11="COUNTS",ISNUMBER(SEARCH("V1",P11)),ISNUMBER(SEARCH("V2",P11)),ISNUMBER(SEARCH("V5",P11))),"A — 100%","B — sample ≥ 30%")
A12: A5.2 | B12: Doc 2 | C12: PROPOSED | D12: V7 — Document & design inspection | F12: Specification text against implementation description; provenance sections; objective card lines | G12: B — sample ≥ 30% | K12: =IFERROR(INDEX('Status Map'!$B$2:$B$12,MATCH(C12,'Status Map'!$A$2:$A$12,0)),"UNDEFINED") | L12: =IFERROR(INDEX('Status Map'!$C$2:$C$12,MATCH(C12,'Status Map'!$A$2:$A$12,0)),"UNDEFINED") | M12: HEADING ONLY | P12: =IF(O12<>"",O12,LEFT(D12,2)) | Q12: =IF(O12<>"","Standards §6",IF(M12="HEADING ONLY","Derived from heading — PROVISIONAL",IF(M12="TEXT NOT IN REGISTRY","No text to derive from — PROVISIONAL","Derived from registered statement"))) | R12: =IF(OR(LEFT(G12,1)="A",L12="COUNTS",ISNUMBER(SEARCH("V1",P12)),ISNUMBER(SEARCH("V2",P12)),ISNUMBER(SEARCH("V5",P12))),"A — 100%","B — sample ≥ 30%")
A13: A5.3 | B13: Doc 2 | C13: — | D13: V7 — Document & design inspection | F13: Specification text against implementation description; provenance sections; objective card lines | G13: B — sample ≥ 30% | K13: =IFERROR(INDEX('Status Map'!$B$2:$B$12,MATCH(C13,'Status Map'!$A$2:$A$12,0)),"UNDEFINED") | L13: =IFERROR(INDEX('Status Map'!$C$2:$C$12,MATCH(C13,'Status Map'!$A$2:$A$12,0)),"UNDEFINED") | M13: HEADING ONLY | P13: =IF(O13<>"",O13,LEFT(D13,2)) | Q13: =IF(O13<>"","Standards §6",IF(M13="HEADING ONLY","Derived from heading — PROVISIONAL",IF(M13="TEXT NOT IN REGISTRY","No text to derive from — PROVISIONAL","Derived from registered statement"))) | R13: =IF(OR(LEFT(G13,1)="A",L13="COUNTS",ISNUMBER(SEARCH("V1",P13)),ISNUMBER(SEARCH("V2",P13)),ISNUMBER(SEARCH("V5",P13))),"A — 100%","B — sample ≥ 30%")
A14: A5.4 | B14: Doc 2 | C14: CANON | D14: V4 — Governance-record evidence | F14: DECISIONS.md entry; ceremony record with tier, countersign, countdown, apply, re-verify; canon_ref present | G14: B — sample ≥ 30% | K14: =IFERROR(INDEX('Status Map'!$B$2:$B$12,MATCH(C14,'Status Map'!$A$2:$A$12,0)),"UNDEFINED") | L14: =IFERROR(INDEX('Status Map'!$C$2:$C$12,MATCH(C14,'Status Map'!$A$2:$A$12,0)),"UNDEFINED") | M14: HEADING ONLY | P14: =IF(O14<>"",O14,LEFT(D14,2)) | Q14: =IF(O14<>"","Standards §6",IF(M14="HEADING ONLY","Derived from heading — PROVISIONAL",IF(M14="TEXT NOT IN REGISTRY","No text to derive from — PROVISIONAL","Derived from registered statement"))) | R14: =IF(OR(LEFT(G14,1)="A",L14="COUNTS",ISNUMBER(SEARCH("V1",P14)),ISNUMBER(SEARCH("V2",P14)),ISNUMBER(SEARCH("V5",P14))),"A — 100%","B — sample ≥ 30%")
A15: A5.5 | B15: Doc 2 | C15: CANON | D15: V7 — Document & design inspection | F15: Specification text against implementation description; provenance sections; objective card lines | G15: B — sample ≥ 30% | K15: =IFERROR(INDEX('Status Map'!$B$2:$B$12,MATCH(C15,'Status Map'!$A$2:$A$12,0)),"UNDEFINED") | L15: =IFERROR(INDEX('Status Map'!$C$2:$C$12,MATCH(C15,'Status Map'!$A$2:$A$12,0)),"UNDEFINED") | M15: HEADING ONLY | P15: =IF(O15<>"",O15,LEFT(D15,2)) | Q15: =IF(O15<>"","Standards §6",IF(M15="HEADING ONLY","Derived from heading — PROVISIONAL",IF(M15="TEXT NOT IN REGISTRY","No text to derive from — PROVISIONAL","Derived from registered statement"))) | R15: =IF(OR(LEFT(G15,1)="A",L15="COUNTS",ISNUMBER(SEARCH("V1",P15)),ISNUMBER(SEARCH("V2",P15)),ISNUMBER(SEARCH("V5",P15))),"A — 100%","B — sample ≥ 30%")
A16: B5.1 | B16: Doc 1 | C16: RULED | D16: V7 — Document & design inspection | F16: Specification text against implementation description; provenance sections; objective card lines | G16: A — 100% | K16: =IFERROR(INDEX('Status Map'!$B$2:$B$12,MATCH(C16,'Status Map'!$A$2:$A$12,0)),"UNDEFINED") | L16: =IFERROR(INDEX('Status Map'!$C$2:$C$12,MATCH(C16,'Status Map'!$A$2:$A$12,0)),"UNDEFINED") | M16: HEADING ONLY | P16: =IF(O16<>"",O16,LEFT(D16,2)) | Q16: =IF(O16<>"","Standards §6",IF(M16="HEADING ONLY","Derived from heading — PROVISIONAL",IF(M16="TEXT NOT IN REGISTRY","No text to derive from — PROVISIONAL","Derived from registered statement"))) | R16: =IF(OR(LEFT(G16,1)="A",L16="COUNTS",ISNUMBER(SEARCH("V1",P16)),ISNUMBER(SEARCH("V2",P16)),ISNUMBER(SEARCH("V5",P16))),"A — 100%","B — sample ≥ 30%")
A17: B5.2 | B17: Doc 1 | C17: — | D17: V6 — Surface inspection | F17: DOM-bound substitution rule or harness receipt; fixed string verbatim; honest-gap variant rendered on null | G17: A — 100% | K17: =IFERROR(INDEX('Status Map'!$B$2:$B$12,MATCH(C17,'Status Map'!$A$2:$A$12,0)),"UNDEFINED") | L17: =IFERROR(INDEX('Status Map'!$C$2:$C$12,MATCH(C17,'Status Map'!$A$2:$A$12,0)),"UNDEFINED") | M17: HEADING ONLY | P17: =IF(O17<>"",O17,LEFT(D17,2)) | Q17: =IF(O17<>"","Standards §6",IF(M17="HEADING ONLY","Derived from heading — PROVISIONAL",IF(M17="TEXT NOT IN REGISTRY","No text to derive from — PROVISIONAL","Derived from registered statement"))) | R17: =IF(OR(LEFT(G17,1)="A",L17="COUNTS",ISNUMBER(SEARCH("V1",P17)),ISNUMBER(SEARCH("V2",P17)),ISNUMBER(SEARCH("V5",P17))),"A — 100%","B — sample ≥ 30%")
A18: B5.3 | B18: Doc 1 | C18: CANON | D18: V7 — Document & design inspection | F18: Specification text against implementation description; provenance sections; objective card lines | G18: A — 100% | K18: =IFERROR(INDEX('Status Map'!$B$2:$B$12,MATCH(C18,'Status Map'!$A$2:$A$12,0)),"UNDEFINED") | L18: =IFERROR(INDEX('Status Map'!$C$2:$C$12,MATCH(C18,'Status Map'!$A$2:$A$12,0)),"UNDEFINED") | M18: HEADING ONLY | P18: =IF(O18<>"",O18,LEFT(D18,2)) | Q18: =IF(O18<>"","Standards §6",IF(M18="HEADING ONLY","Derived from heading — PROVISIONAL",IF(M18="TEXT NOT IN REGISTRY","No text to derive from — PROVISIONAL","Derived from registered statement"))) | R18: =IF(OR(LEFT(G18,1)="A",L18="COUNTS",ISNUMBER(SEARCH("V1",P18)),ISNUMBER(SEARCH("V2",P18)),ISNUMBER(SEARCH("V5",P18))),"A — 100%","B — sample ≥ 30%")
A19: B5.4 | B19: Doc 1 | C19: CANON | D19: V3 — Record evidence | F19: Ledger rows inspected; hash-chain verifier receipt; refused operations present on identical terms | G19: A — 100% | K19: =IFERROR(INDEX('Status Map'!$B$2:$B$12,MATCH(C19,'Status Map'!$A$2:$A$12,0)),"UNDEFINED") | L19: =IFERROR(INDEX('Status Map'!$C$2:$C$12,MATCH(C19,'Status Map'!$A$2:$A$12,0)),"UNDEFINED") | M19: HEADING ONLY | P19: =IF(O19<>"",O19,LEFT(D19,2)) | Q19: =IF(O19<>"","Standards §6",IF(M19="HEADING ONLY","Derived from heading — PROVISIONAL",IF(M19="TEXT NOT IN REGISTRY","No text to derive from — PROVISIONAL","Derived from registered statement"))) | R19: =IF(OR(LEFT(G19,1)="A",L19="COUNTS",ISNUMBER(SEARCH("V1",P19)),ISNUMBER(SEARCH("V2",P19)),ISNUMBER(SEARCH("V5",P19))),"A — 100%","B — sample ≥ 30%")
A20: B5.5 | B20: Doc 1 | C20: RULED | D20: V7 — Document & design inspection | F20: Specification text against implementation description; provenance sections; objective card lines | G20: A — 100% | K20: =IFERROR(INDEX('Status Map'!$B$2:$B$12,MATCH(C20,'Status Map'!$A$2:$A$12,0)),"UNDEFINED") | L20: =IFERROR(INDEX('Status Map'!$C$2:$C$12,MATCH(C20,'Status Map'!$A$2:$A$12,0)),"UNDEFINED") | M20: HEADING ONLY | P20: =IF(O20<>"",O20,LEFT(D20,2)) | Q20: =IF(O20<>"","Standards §6",IF(M20="HEADING ONLY","Derived from heading — PROVISIONAL",IF(M20="TEXT NOT IN REGISTRY","No text to derive from — PROVISIONAL","Derived from registered statement"))) | R20: =IF(OR(LEFT(G20,1)="A",L20="COUNTS",ISNUMBER(SEARCH("V1",P20)),ISNUMBER(SEARCH("V2",P20)),ISNUMBER(SEARCH("V5",P20))),"A — 100%","B — sample ≥ 30%")
... A28: A5.2 | B28: Doc 15 | C28: — | D28: V7 — Document & design inspection | F28: Specification text against implementation description; provenance sections; objective card lines | G28: B — sample ≥ 30% | K28: =IFERROR(INDEX('Status Map'!$B$2:$B$12,MATCH(C28,'Status Map'!$A$2:$A$12,0)),"UNDEFINED") | L28: =IFERROR(INDEX('Status Map'!$C$2:$C$12,MATCH(C28,'Status Map'!$A$2:$A$12,0)),"UNDEFINED") | M28: HEADING ONLY | P28: =IF(O28<>"",O28,LEFT(D28,2)) | Q28: =IF(O28<>"","Standards §6",IF(M28="HEADING ONLY","Derived from heading — PROVISIONAL",IF(M28="TEXT NOT IN REGISTRY","No text to derive from — PROVISIONAL","Derived from registered statement"))) | R28: =IF(OR(LEFT(G28,1)="A",L28="COUNTS",ISNUMBER(SEARCH("V1",P28)),ISNUMBER(SEARCH("V2",P28)),ISNUMBER(SEARCH("V5",P28))),"A — 100%","B — sample ≥ 30%")
A29: A5.3 | B29: Doc 15 | C29: DETERMINED | D29: V7 — Document & design inspection | F29: Specification text against implementation description; provenance sections; objective card lines | G29: B — sample ≥ 30% | K29: =IFERROR(INDEX('Status Map'!$B$2:$B$12,MATCH(C29,'Status Map'!$A$2:$A$12,0)),"UNDEFINED") | L29: COUNTS | M29: HEADING ONLY | P29: =IF(O29<>"",O29,LEFT(D29,2)) | Q29: =IF(O29<>"","Standards §6",IF(M29="HEADING ONLY","Derived from heading — PROVISIONAL",IF(M29="TEXT NOT IN REGISTRY","No text to derive from — PROVISIONAL","Derived from registered statement"))) | R29: =IF(OR(LEFT(G29,1)="A",L29="COUNTS",ISNUMBER(SEARCH("V1",P29)),ISNUMBER(SEARCH("V2",P29)),ISNUMBER(SEARCH("V5",P29))),"A — 100%","B — sample ≥ 30%")
A30: A5.1 | B30: Doc 3 | C30: — | D30: V7 — Document & design inspection | F30: Specification text against implementation description; provenance sections; objective card lines | G30: A — 100% | K30: =IFERROR(INDEX('Status Map'!$B$2:$B$12,MATCH(C30,'Status Map'!$A$2:$A$12,0)),"UNDEFINED") | L30: =IFERROR(INDEX('Status Map'!$C$2:$C$12,MATCH(C30,'Status Map'!$A$2:$A$12,0)),"UNDEFINED") | M30: HEADING ONLY | P30: =IF(O30<>"",O30,LEFT(D30,2)) | Q30: =IF(O30<>"","Standards §6",IF(M30="HEADING ONLY","Derived from heading — PROVISIONAL",IF(M30="TEXT NOT IN REGISTRY","No text to derive from — PROVISIONAL","Derived from registered statement"))) | R30: =IF(OR(LEFT(G30,1)="A",L30="COUNTS",ISNUMBER(SEARCH("V1",P30)),ISNUMBER(SEARCH("V2",P30)),ISNUMBER(SEARCH("V5",P30))),"A — 100%","B — sample ≥ 30%")
A31: A5.10 | B31: Doc 3 | C31: — | D31: V7 — Document & design inspection | F31: Specification text against implementation description; provenance sections; objective card lines | G31: A — 100% | K31: =IFERROR(INDEX('Status Map'!$B$2:$B$12,MATCH(C31,'Status Map'!$A$2:$A$12,0)),"UNDEFINED") | L31: =IFERROR(INDEX('Status Map'!$C$2:$C$12,MATCH(C31,'Status Map'!$A$2:$A$12,0)),"UNDEFINED") | M31: HEADING ONLY | P31: =IF(O31<>"",O31,LEFT(D31,2)) | Q31: =IF(O31<>"","Standards §6",IF(M31="HEADING ONLY","Derived from heading — PROVISIONAL",IF(M31="TEXT NOT IN REGISTRY","No text to derive from — PROVISIONAL","Derived from registered statement"))) | R31: =IF(OR(LEFT(G31,1)="A",L31="COUNTS",ISNUMBER(SEARCH("V1",P31)),ISNUMBER(SEARCH("V2",P31)),ISNUMBER(SEARCH("V5",P31))),"A — 100%","B — sample ≥ 30%")
A32: A5.11 | B32: Doc 3 | C32: — | D32: V7 — Document & design inspection | F32: Specification text against implementation description; provenance sections; objective card lines | G32: A — 100% | K32: =IFERROR(INDEX('Status Map'!$B$2:$B$12,MATCH(C32,'Status Map'!$A$2:$A$12,0)),"UNDEFINED") | L32: =IFERROR(INDEX('Status Map'!$C$2:$C$12,MATCH(C32,'Status Map'!$A$2:$A$12,0)),"UNDEFINED") | M32: HEADING ONLY | P32: =IF(O32<>"",O32,LEFT(D32,2)) | Q32: =IF(O32<>"","Standards §6",IF(M32="HEADING ONLY","Derived from heading — PROVISIONAL",IF(M32="TEXT NOT IN REGISTRY","No text to derive from — PROVISIONAL","Derived from registered statement"))) | R32: =IF(OR(LEFT(G32,1)="A",L32="COUNTS",ISNUMBER(SEARCH("V1",P32)),ISNUMBER(SEARCH("V2",P32)),ISNUMBER(SEARCH("V5",P32))),"A — 100%","B — sample ≥ 30%")
A33: A5.12 | B33: Doc 3 | C33: — | D33: V7 — Document & design inspection | F33: Specification text against implementation description; provenance sections; objective card lines | G33: A — 100% | K33: =IFERROR(INDEX('Status Map'!$B$2:$B$12,MATCH(C33,'Status Map'!$A$2:$A$12,0)),"UNDEFINED") | L33: =IFERROR(INDEX('Status Map'!$C$2:$C$12,MATCH(C33,'Status Map'!$A$2:$A$12,0)),"UNDEFINED") | M33: HEADING ONLY | P33: =IF(O33<>"",O33,LEFT(D33,2)) | Q33: =IF(O33<>"","Standards §6",IF(M33="HEADING ONLY","Derived from heading — PROVISIONAL",IF(M33="TEXT NOT IN REGISTRY","No text to derive from — PROVISIONAL","Derived from registered statement"))) | R33: =IF(OR(LEFT(G33,1)="A",L33="COUNTS",ISNUMBER(SEARCH("V1",P33)),ISNUMBER(SEARCH("V2",P33)),ISNUMBER(SEARCH("V5",P33))),"A — 100%","B — sample ≥ 30%")
A34: A5.13 | B34: Doc 3 | C34: — | D34: V7 — Document & design inspection | F34: Specification text against implementation description; provenance sections; objective card lines | G34: A — 100% | K34: =IFERROR(INDEX('Status Map'!$B$2:$B$12,MATCH(C34,'Status Map'!$A$2:$A$12,0)),"UNDEFINED") | L34: =IFERROR(INDEX('Status Map'!$C$2:$C$12,MATCH(C34,'Status Map'!$A$2:$A$12,0)),"UNDEFINED") | M34: HEADING ONLY | P34: =IF(O34<>"",O34,LEFT(D34,2)) | Q34: =IF(O34<>"","Standards §6",IF(M34="HEADING ONLY","Derived from heading — PROVISIONAL",IF(M34="TEXT NOT IN REGISTRY","No text to derive from — PROVISIONAL","Derived from registered statement"))) | R34: =IF(OR(LEFT(G34,1)="A",L34="COUNTS",ISNUMBER(SEARCH("V1",P34)),ISNUMBER(SEARCH("V2",P34)),ISNUMBER(SEARCH("V5",P34))),"A — 100%","B — sample ≥ 30%")
A35: A5.14 | B35: Doc 3 | C35: — | D35: V7 — Document & design inspection | F35: Specification text against implementation description; provenance sections; objective card lines | G35: A — 100% | K35: =IFERROR(INDEX('Status Map'!$B$2:$B$12,MATCH(C35,'Status Map'!$A$2:$A$12,0)),"UNDEFINED") | L35: =IFERROR(INDEX('Status Map'!$C$2:$C$12,MATCH(C35,'Status Map'!$A$2:$A$12,0)),"UNDEFINED") | M35: HEADING ONLY | N35: C-6.4.7 | O35: V5 | P35: =IF(O35<>"",O35,LEFT(D35,2)) | Q35: =IF(O35<>"","Standards §6",IF(M35="HEADING ONLY","Derived from heading — PROVISIONAL",IF(M35="TEXT NOT IN REGISTRY","No text to derive from — PROVISIONAL","Derived from registered statement"))) | R35: =IF(OR(LEFT(G35,1)="A",L35="COUNTS",ISNUMBER(SEARCH("V1",P35)),ISNUMBER(SEARCH("V2",P35)),ISNUMBER(SEARCH("V5",P35))),"A — 100%","B — sample ≥ 30%")
A36: A5.2 | B36: Doc 3 | C36: — | D36: V7 — Document & design inspection | F36: Specification text against implementation description; provenance sections; objective card lines | G36: A — 100% | K36: =IFERROR(INDEX('Status Map'!$B$2:$B$12,MATCH(C36,'Status Map'!$A$2:$A$12,0)),"UNDEFINED") | L36: =IFERROR(INDEX('Status Map'!$C$2:$C$12,MATCH(C36,'Status Map'!$A$2:$A$12,0)),"UNDEFINED") | M36: HEADING ONLY | N36: C-6.4.3, C-6.4.4 | O36: V2 + V4 + V6 | P36: =IF(O36<>"",O36,LEFT(D36,2)) | Q36: =IF(O36<>"","Standards §6",IF(M36="HEADING ONLY","Derived from heading — PROVISIONAL",IF(M36="TEXT NOT IN REGISTRY","No text to derive from — PROVISIONAL","Derived from registered statement"))) | R36: =IF(OR(LEFT(G36,1)="A",L36="COUNTS",ISNUMBER(SEARCH("V1",P36)),ISNUMBER(SEARCH("V2",P36)),ISNUMBER(SEARCH("V5",P36))),"A — 100%","B — sample ≥ 30%")
A37: A5.3 | B37: Doc 3 | C37: — | D37: V4 — Governance-record evidence | F37: DECISIONS.md entry; ceremony record with tier, countersign, countdown, apply, re-verify; canon_ref present | G37: A — 100% | K37: =IFERROR(INDEX('Status Map'!$B$2:$B$12,MATCH(C37,'Status Map'!$A$2:$A$12,0)),"UNDEFINED") | L37: =IFERROR(INDEX('Status Map'!$C$2:$C$12,MATCH(C37,'Status Map'!$A$2:$A$12,0)),"UNDEFINED") | M37: HEADING ONLY | N37: C-6.4.5, C-6.4.7 | O37: V2 + V5 | P37: =IF(O37<>"",O37,LEFT(D37,2)) | Q37: =IF(O37<>"","Standards §6",IF(M37="HEADING ONLY","Derived from heading — PROVISIONAL",IF(M37="TEXT NOT IN REGISTRY","No text to derive from — PROVISIONAL","Derived from registered statement"))) | R37: =IF(OR(LEFT(G37,1)="A",L37="COUNTS",ISNUMBER(SEARCH("V1",P37)),ISNUMBER(SEARCH("V2",P37)),ISNUMBER(SEARCH("V5",P37))),"A — 100%","B — sample ≥ 30%")
A38: A5.4 | B38: Doc 3 | C38: — | D38: V7 — Document & design inspection | F38: Specification text against implementation description; provenance sections; objective card lines | G38: A — 100% | K38: =IFERROR(INDEX('Status Map'!$B$2:$B$12,MATCH(C38,'Status Map'!$A$2:$A$12,0)),"UNDEFINED") | L38: =IFERROR(INDEX('Status Map'!$C$2:$C$12,MATCH(C38,'Status Map'!$A$2:$A$12,0)),"UNDEFINED") | M38: HEADING ONLY | P38: =IF(O38<>"",O38,LEFT(D38,2)) | Q38: =IF(O38<>"","Standards §6",IF(M38="HEADING ONLY","Derived from heading — PROVISIONAL",IF(M38="TEXT NOT IN REGISTRY","No text to derive from — PROVISIONAL","Derived from registered statement"))) | R38: =IF(OR(LEFT(G38,1)="A",L38="COUNTS",ISNUMBER(SEARCH("V1",P38)),ISNUMBER(SEARCH("V2",P38)),ISNUMBER(SEARCH("V5",P38))),"A — 100%","B — sample ≥ 30%")
A39: A5.5 | B39: Doc 3 | C39: — | D39: V7 — Document & design inspection | F39: Specification text against implementation description; provenance sections; objective card lines | G39: A — 100% | K39: =IFERROR(INDEX('Status Map'!$B$2:$B$12,MATCH(C39,'Status Map'!$A$2:$A$12,0)),"UNDEFINED") | L39: =IFERROR(INDEX('Status Map'!$C$2:$C$12,MATCH(C39,'Status Map'!$A$2:$A$12,0)),"UNDEFINED") | M39: HEADING ONLY | P39: =IF(O39<>"",O39,LEFT(D39,2)) | Q39: =IF(O39<>"","Standards §6",IF(M39="HEADING ONLY","Derived from heading — PROVISIONAL",IF(M39="TEXT NOT IN REGISTRY","No text to derive from — PROVISIONAL","Derived from registered statement"))) | R39: =IF(OR(LEFT(G39,1)="A",L39="COUNTS",ISNUMBER(SEARCH("V1",P39)),ISNUMBER(SEARCH("V2",P39)),ISNUMBER(SEARCH("V5",P39))),"A — 100%","B — sample ≥ 30%")
A40: A5.6 | B40: Doc 3 | C40: — | D40: V7 — Document & design inspection | F40: Specification text against implementation description; provenance sections; objective card lines | G40: A — 100% | K40: =IFERROR(INDEX('Status Map'!$B$2:$B$12,MATCH(C40,'Status Map'!$A$2:$A$12,0)),"UNDEFINED") | L40: =IFERROR(INDEX('Status Map'!$C$2:$C$12,MATCH(C40,'Status Map'!$A$2:$A$12,0)),"UNDEFINED") | M40: HEADING ONLY | P40: =IF(O40<>"",O40,LEFT(D40,2)) | Q40: =IF(O40<>"","Standards §6",IF(M40="HEADING ONLY","Derived from heading — PROVISIONAL",IF(M40="TEXT NOT IN REGISTRY","No text to derive from — PROVISIONAL","Derived from registered statement"))) | R40: =IF(OR(LEFT(G40,1)="A",L40="COUNTS",ISNUMBER(SEARCH("V1",P40)),ISNUMBER(SEARCH("V2",P40)),ISNUMBER(SEARCH("V5",P40))),"A — 100%","B — sample ≥ 30%")
A41: A5.7 | B41: Doc 3 | C41: — | D41: V7 — Document & design inspection | F41: Specification text against implementation description; provenance sections; objective card lines | G41: A — 100% | K41: =IFERROR(INDEX('Status Map'!$B$2:$B$12,MATCH(C41,'Status Map'!$A$2:$A$12,0)),"UNDEFINED") | L41: =IFERROR(INDEX('Status Map'!$C$2:$C$12,MATCH(C41,'Status Map'!$A$2:$A$12,0)),"UNDEFINED") | M41: HEADING ONLY | P41: =IF(O41<>"",O41,LEFT(D41,2)) | Q41: =IF(O41<>"","Standards §6",IF(M41="HEADING ONLY","Derived from heading — PROVISIONAL",IF(M41="TEXT NOT IN REGISTRY","No text to derive from — PROVISIONAL","Derived from registered statement"))) | R41: =IF(OR(LEFT(G41,1)="A",L41="COUNTS",ISNUMBER(SEARCH("V1",P41)),ISNUMBER(SEARCH("V2",P41)),ISNUMBER(SEARCH("V5",P41))),"A — 100%","B — sample ≥ 30%")
A42: A5.8 | B42: Doc 3 | C42: — | D42: V7 — Document & design inspection | F42: Specification text against implementation description; provenance sections; objective card lines | G42: A — 100% | K42: =IFERROR(INDEX('Status Map'!$B$2:$B$12,MATCH(C42,'Status Map'!$A$2:$A$12,0)),"UNDEFINED") | L42: =IFERROR(INDEX('Status Map'!$C$2:$C$12,MATCH(C42,'Status Map'!$A$2:$A$12,0)),"UNDEFINED") | M42: HEADING ONLY | P42: =IF(O42<>"",O42,LEFT(D42,2)) | Q42: =IF(O42<>"","Standards §6",IF(M42="HEADING ONLY","Derived from heading — PROVISIONAL",IF(M42="TEXT NOT IN REGISTRY","No text to derive from — PROVISIONAL","Derived from registered statement"))) | R42: =IF(OR(LEFT(G42,1)="A",L42="COUNTS",ISNUMBER(SEARCH("V1",P42)),ISNUMBER(SEARCH("V2",P42)),ISNUMBER(SEARCH("V5",P42))),"A — 100%","B — sample ≥ 30%")
A43: A5.9 | B43: Doc 3 | C43: — | D43: V7 — Document & design inspection | F43: Specification text against implementation description; provenance sections; objective card lines | G43: A — 100% | K43: =IFERROR(INDEX('Status Map'!$B$2:$B$12,MATCH(C43,'Status Map'!$A$2:$A$12,0)),"UNDEFINED") | L43: =IFERROR(INDEX('Status Map'!$C$2:$C$12,MATCH(C43,'Status Map'!$A$2:$A$12,0)),"UNDEFINED") | M43: HEADING ONLY | P43: =IF(O43<>"",O43,LEFT(D43,2)) | Q43: =IF(O43<>"","Standards §6",IF(M43="HEADING ONLY","Derived from heading — PROVISIONAL",IF(M43="TEXT NOT IN REGISTRY","No text to derive from — PROVISIONAL","Derived from registered statement"))) | R43: =IF(OR(LEFT(G43,1)="A",L43="COUNTS",ISNUMBER(SEARCH("V1",P43)),ISNUMBER(SEARCH("V2",P43)),ISNUMBER(SEARCH("V5",P43))),"A — 100%","B — sample ≥ 30%")
A44: B5.1 | B44: Doc 3 | C44: CANON | D44: V7 — Document & design inspection | F44: Specification text against implementation description; provenance sections; objective card lines | G44: A — 100% | K44: =IFERROR(INDEX('Status Map'!$B$2:$B$12,MATCH(C44,'Status Map'!$A$2:$A$12,0)),"UNDEFINED") | L44: =IFERROR(INDEX('Status Map'!$C$2:$C$12,MATCH(C44,'Status Map'!$A$2:$A$12,0)),"UNDEFINED") | M44: HEADING ONLY | P44: =IF(O44<>"",O44,LEFT(D44,2)) | Q44: =IF(O44<>"","Standards §6",IF(M44="HEADING ONLY","Derived from heading — PROVISIONAL",IF(M44="TEXT NOT IN REGISTRY","No text to derive from — PROVISIONAL","Derived from registered statement"))) | R44: =IF(OR(LEFT(G44,1)="A",L44="COUNTS",ISNUMBER(SEARCH("V1",P44)),ISNUMBER(SEARCH("V2",P44)),ISNUMBER(SEARCH("V5",P44))),"A — 100%","B — sample ≥ 30%")
A45: B5.2 | B45: Doc 3 | C45: CANON | D45: V1 — Test evidence | F45: Golden-input, byte-identical output; RED-first test ID; ratchet manifest entry | G45: A — 100% | K45: =IFERROR(INDEX('Status Map'!$B$2:$B$12,MATCH(C45,'Status Map'!$A$2:$A$12,0)),"UNDEFINED") | L45: =IFERROR(INDEX('Status Map'!$C$2:$C$12,MATCH(C45,'Status Map'!$A$2:$A$12,0)),"UNDEFINED") | M45: HEADING ONLY | P45: =IF(O45<>"",O45,LEFT(D45,2)) | Q45: =IF(O45<>"","Standards §6",IF(M45="HEADING ONLY","Derived from heading — PROVISIONAL",IF(M45="TEXT NOT IN REGISTRY","No text to derive from — PROVISIONAL","Derived from registered statement"))) | R45: =IF(OR(LEFT(G45,1)="A",L45="COUNTS",ISNUMBER(SEARCH("V1",P45)),ISNUMBER(SEARCH("V2",P45)),ISNUMBER(SEARCH("V5",P45))),"A — 100%","B — sample ≥ 30%")
A46: B5.3 | B46: Doc 3 | C46: CANON | D46: V7 — Document & design inspection | F46: Specification text against implementation description; provenance sections; objective card lines | G46: A — 100% | K46: =IFERROR(INDEX('Status Map'!$B$2:$B$12,MATCH(C46,'Status Map'!$A$2:$A$12,0)),"UNDEFINED") | L46: =IFERROR(INDEX('Status Map'!$C$2:$C$12,MATCH(C46,'Status Map'!$A$2:$A$12,0)),"UNDEFINED") | M46: HEADING ONLY | P46: =IF(O46<>"",O46,LEFT(D46,2)) | Q46: =IF(O46<>"","Standards §6",IF(M46="HEADING ONLY","Derived from heading — PROVISIONAL",IF(M46="TEXT NOT IN REGISTRY","No text to derive from — PROVISIONAL","Derived from registered statement"))) | R46: =IF(OR(LEFT(G46,1)="A",L46="COUNTS",ISNUMBER(SEARCH("V1",P46)),ISNUMBER(SEARCH("V2",P46)),ISNUMBER(SEARCH("V5",P46))),"A — 100%","B — sample ≥ 30%")
A47: B5.4 | B47: Doc 3 | C47: CANON | D47: V3 — Record evidence | F47: Ledger rows inspected; hash-chain verifier receipt; refused operations present on identical terms | G47: A — 100% | K47: =IFERROR(INDEX('Status Map'!$B$2:$B$12,MATCH(C47,'Status Map'!$A$2:$A$12,0)),"UNDEFINED") | L47: =IFERROR(INDEX('Status Map'!$C$2:$C$12,MATCH(C47,'Status Map'!$A$2:$A$12,0)),"UNDEFINED") | M47: HEADING ONLY | P47: =IF(O47<>"",O47,LEFT(D47,2)) | Q47: =IF(O47<>"","Standards §6",IF(M47="HEADING ONLY","Derived from heading — PROVISIONAL",IF(M47="TEXT NOT IN REGISTRY","No text to derive from — PROVISIONAL","Derived from registered statement"))) | R47: =IF(OR(LEFT(G47,1)="A",L47="COUNTS",ISNUMBER(SEARCH("V1",P47)),ISNUMBER(SEARCH("V2",P47)),ISNUMBER(SEARCH("V5",P47))),"A — 100%","B — sample ≥ 30%")
...

Sheet Status Map
A1: Raw status (as registered) | B1: Normalised status | C1: Weight in promise roll-up | D1: Rows | E1: Basis / owner action
A2: CANON | B2: CANON | C2: COUNTS | D2: =COUNTIF('QA Verification'!$C$2:$C$603,A2) | E2: Ratified.
A3: RULED | B3: RULED | C3: COUNTS | D3: =COUNTIF('QA Verification'!$C$2:$C$603,A3) | E3: Ratified by ruling. The DECISIONS.md entry is confirmed by the auditor before the rule is weighed (Standards 2.5).
A4: PROPOSED | B4: PROPOSED | C4: UNRATIFIED | D4: =COUNTIF('QA Verification'!$C$2:$C$603,A4) | E4: Examined and given a verdict; excluded from the ratified roll-up, included in the full roll-up.
A5: PROPOSED (pending ratification) | B5: PROPOSED | C5: UNRATIFIED | D5: =COUNTIF('QA Verification'!$C$2:$C$603,A5) | E5: As PROPOSED.
A6: DEFAULT (draft; R2 open) | B6: DEFAULT | C6: UNRATIFIED | D6: =COUNTIF('QA Verification'!$C$2:$C$603,A6) | E6: As PROPOSED.
A7: OPEN | B7: OPEN | C7: OPEN | D7: =COUNTIF('QA Verification'!$C$2:$C$603,A7) | E7: Recorded NOT EXAMINED with reason OPEN.
A8: — | B8: UNDEFINED | C8: UNDEFINED | D8: =COUNTIF('QA Verification'!$C$2:$C$603,A8) | E8: OWNER ACTION: status not in the vocabulary. Rule CANON, RULED, PROPOSED, DEFAULT or OPEN before the audit target is tagged. Until ruled: examined, excluded from the ratified roll-up, listed in the registry-defect annex.
A9: — (see heading) | B9: UNDEFINED | C9: UNDEFINED | D9: =COUNTIF('QA Verification'!$C$2:$C$603,A9) | E9: OWNER ACTION: as above. The status is said to sit in the source heading; transcribe it.
A10: See xlsx | B10: UNDEFINED | C10: UNDEFINED | D10: =COUNTIF('QA Verification'!$C$2:$C$603,A10) | E10: OWNER ACTION: status and text sit in Security_Assurance_Promise_Set.xlsx, which was not issued with the registries. Supply it (Standards 9.1) and transcribe the status.
A11: DETERMINED | B11: RULED | C11: COUNTS | D11: =COUNTIF('QA Verification'!$C$2:$C$603,A11) | E11: Owner ruling 21 Sep 2026: a determination and an owner-directed canon entry are ratified acts; weight COUNTS.
A12: OWNER-DIRECTED → CANON (R3/R5/R7/R9 strikeable) | B12: RULED | C12: COUNTS | D12: =COUNTIF('QA Verification'!$C$2:$C$603,A12) | E12: Owner ruling 21 Sep 2026: a determination and an owner-directed canon entry are ratified acts; weight COUNTS.
A13: Total | D13: =SUM(D2:D12)
A15: Columns B and C are the only place status weight is set. Edit them here and every derived column in QA Verification, and the Audit Summary, recalculates. Yellow = input; grey = formula.

Sheet Check Register
A1: Check ID | B1: Part | C1: Domain | D1: Check | E1: Standard | F1: Class / method | G1: FAIL or DEFECT looks like | H1: Registry rules resolved (document-qualified) | I1: Citations that do not resolve in the registry | J1: Verdict / rating | K1: Evidence examined (class · artefact) | L1: Observed | M1: Severity | N1: Finding ref | O1: Commit · ratchet
A2: C-6.1.1 | B2: I Conformance | C2: 6.1 Build discipline | D2: Every seal is a §3.3 three-commit seal; Commit-B and Commit-C bank the prior SHA | E2: SO §3.3 | F2: V4 | G2: A seal with an unbanked SHA; a fixup that rewrites history
A3: C-6.1.2 | B3: I Conformance | C3: 6.1 Build discipline | D3: Full BASELINE_GUARD=1 sweep before Commit-B; byte-identical double-green recorded | E3: SO §3.3; R-18 close standard | F3: V1 | G3: A seal note showing targeted invariants only
A4: C-6.1.3 | B4: I Conformance | C4: 6.1 Build discipline | D4: Ratchet floor moves only from measurement, reconciled line by line; no silent rebaselining | E4: SO §3 | F4: V4 | G4: A floor bump without a reconciliation record
A5: C-6.1.4 | B5: I Conformance | C5: 6.1 Build discipline | D5: Every generated requirement carries canon_ref; the documentation check fails on its absence | E5: R-18 effect 2 | F5: V4 | G5: A requirements file with a row lacking canon_ref and passing CI
A6: C-6.1.5 | B6: I Conformance | C6: 6.1 Build discipline | D6: Every milestone has a pinned objective card; every seal cites a card line | E6: SO §6.2 | F6: V4 | G6: A seal message citing no line; a card whose MUST-DO has no exit evidence
A7: C-6.1.6 | B7: I Conformance | C7: 6.1 Build discipline | D7: A gate-satisfaction claim cites absence-of-blocker evidence per line | E7: SO §6.2 amendment | F7: V4 | G7: “Gate satisfied” resting on “waves closed” alone
A8: C-6.1.7 | B8: I Conformance | C8: 6.1 Build discipline | D8: Order of authority observed: no lower layer amends a higher one | E8: R-18 effect 1 | F8: V7 | G8: An SER clause contradicting a CANON rule with no erratum
A9: C-6.2.1 | B9: I Conformance | C9: 6.2 Trusted computing base and determinism | D9: Membership test is BA-1.1: deterministic and failure falsifies a stated guarantee | E9: Doc 0 BA-1.1; R-18 effect 7 | F9: V7 | G9: A membership table using a different test | I9: Doc 0 BA-1.1 — no registry row
A10: C-6.2.2 | B10: I Conformance | C10: 6.2 Trusted computing base and determinism | D10: Every enumerated member has a golden-input, byte-identical test | E10: B.8; tcb_enumeration_v1; determinism_inventory_v1 (v1.0 cited DET-1, DET-2 — miscited, RD-06) | F10: V1 | G10: A member with no test, or a test without a stated golden input | I10: B.8 — no registry row; DET-1 — DET-1 in the registry is an OPEN item on a CIF halt mechanism, not a golden-input test rule; DET-2 — DET-2 in the registry concerns Mtafiti classification confirmation, not a golden-input test rule
A11: C-6.2.3 | B11: I Conformance | C11: 6.2 Trusted computing base and determinism | D11: No learned component participates in any TCB decision | E11: Attribute 10 | F11: V2 | G11: A model output reachable by a decision function
A12: C-6.2.4 | B12: I Conformance | C12: 6.2 Trusted computing base and determinism | D12: Every member refuses when its own check cannot complete | E12: FP-1, FP-2 | F12: V5 | G12: A member returning a result under injected failure | H12: failure_posture_v1 · FP-1; failure_posture_v1 · FP-2
A13: C-6.2.5 | B13: I Conformance | C13: 6.2 Trusted computing base and determinism | D13: Components in the build but outside the enumeration are absent | E13: tcb_enumeration_v1 method | F13: V7 | G13: A decision-bearing component not in the table
A14: C-6.3.1 | B14: I Conformance | C14: 6.3 The chokepoint and custody | D14: Exactly one function invokes the external model client; the build fails on a second | E14: Doc 1 A5.1 | F14: V2 | G14: A second call site, an import outside the allow-list, or a scan that misses call sites | H14: Doc 1 · A5.1
A15: C-6.3.2 | B15: I Conformance | C15: 6.3 The chokepoint and custody | D15: Custody sequence runs on every call: mask before send, re-identify only inside | E15: DAP-7 | F15: V1 + V5 | G15: A path on which masking is conditional or skippable | H15: DAP Backend spec · DAP-7
A16: C-6.3.3 | B16: I Conformance | C16: 6.3 The chokepoint and custody | D16: No parameter on invoke() alters whether custody runs; tenant_id is required, never Optional | E16: DAP-7 Option D ruling | F16: V2 | G16: A bypass-shaped parameter; an Optional tenant scope | H16: DAP Backend spec · DAP-7
A17: C-6.3.4 | B17: I Conformance | C17: 6.3 The chokepoint and custody | D17: Outbound network is allow-listed; unlisted destinations refuse | E17: Doc 1; ENT-18 | F17: V5 | G17: A connection to an unlisted host succeeding | H17: entitlement_service_v1 · ENT-18
A18: C-6.3.5 | B18: I Conformance | C18: 6.3 The chokepoint and custody | D18: Crossing policy is integrity-verified at load; unverifiable policy is a closed gate | E18: SEC-1 | F18: V5 | G18: A tampered policy loading | H18: security_architecture_v1 · SEC-1
A19: C-6.3.6 | B19: I Conformance | C19: 6.3 The chokepoint and custody | D19: Every crossing is receipted with provider and model version | E19: Doc 1 A5.7; V-4 | F19: V3 | G19: A crossing with no row, or a row without provider and version | H19: Doc 1 · A5.7
A20: C-6.3.7 | B20: I Conformance | C20: 6.3 The chokepoint and custody | D20: Every crossing event reaches the Watch input seat before the call returns; an unobservable crossing does not happen | E20: Doc 3 A3; W1f ruling | F20: V5 | G20: A call completing with the seat unreachable | I20: Doc 3 A3 — no registry row
A21: C-6.4.1 | B21: I Conformance | C21: 6.4 The Watch | D21: Grey Mirror can assert facts and cannot block, throttle, notify, or act | E21: Doc 3 A2 | F21: V2 | G21: A detection component with an action path | I21: Doc 3 A2 — no registry row
A22: C-6.4.2 | B22: I Conformance | C22: 6.4 The Watch | D22: Mkono acts only on a verdict whose signature verifies | E22: SER C.3.5 I-1; R-18 effect 3 | F22: V1 + V5 | G22: An action taken on an unsigned or unverified verdict
A23: C-6.4.3 | B23: I Conformance | C23: 6.4 The Watch | D23: The verdict schema has no confidence, score, strength, or probability field; certificate is evidence only | E23: Doc 3 A5.2; watch_learning_v1 A5.19 | F23: V2 + V6 | G23: Any numeric field on the verdict that enters the action decision | H23: Doc 3 · A5.2; watch_learning_v1 · A5.19
A24: C-6.4.4 | B24: I Conformance | C24: 6.4 The Watch | D24: Severance keys to the closed signal registry; the registry is changed only by ceremony | E24: Doc 3 A5.2; watch_learning_v1 A5.20; RBM-23 | F24: V4 | G24: A severance triggered from outside the registry; a registry edit without a ceremony record | H24: Doc 3 · A5.2; watch_learning_v1 · A5.20; watch_learning_v1 · RBM-23
A25: C-6.4.5 | B25: I Conformance | C25: 6.4 The Watch | D25: Response ladder is annotate · shape · contain · sever; destroy does not exist | E25: Doc 3 A5.3; T-c ruling | F25: V2 | G25: A “destroy” action class in any schema or code path | H25: Doc 3 · A5.3
A26: C-6.4.6 | B26: I Conformance | C26: 6.4 The Watch | D26: Contain and sever freeze the session; the runtime is not deleted | E26: AC-13; R-18 effect 6 | F26: V5 | G26: A sever that removes the runtime pod | H26: serving_integrity_v1 · AC-13
A27: C-6.4.7 | B27: I Conformance | C27: 6.4 The Watch | D27: Every automatic action is reversible and time-limited; blast budget enforced | E27: Doc 3 A5.3, Doc 3 A5.14 | F27: V5 | G27: An automatic action with no expiry or no reversal path | H27: Doc 3 · A5.3; Doc 3 · A5.14
A28: C-6.4.8 | B28: I Conformance | C28: 6.4 The Watch | D28: Certificate requirements are system-TCB class; the ratifying human is named | E28: watch_learning_v1 A5.20; R-16 | F28: V4 | G28: A requirement admitted without the ceremony or the named ratifier | H28: watch_learning_v1 · A5.20
A29: C-6.5.1 | B29: I Conformance | C29: 6.5 The Ledger | D29: Single writer; hash chain intact; append-only — no update or delete path | E29: Doc 5; B.4; BR-8.1 | F29: V2 + V3 | G29: A second writer; a row altered; a delete method reachable | H29: Governance Architecture · BR-8.1 | I29: B.4 — no registry row
A30: C-6.5.2 | B30: I Conformance | C30: 6.5 The Ledger | D30: Row schema is the ratified 17-field schema; frozen as a contract | E30: B-M10-Q1 ruling | F30: V6 | G30: A schema with a field added or removed outside ceremony
A31: C-6.5.3 | B31: I Conformance | C31: 6.5 The Ledger | D31: Refused operations produce rows on the same terms as accepted | E31: BR-8.1; DAP-15 | F31: V3 | G31: A refusal with no row | H31: Governance Architecture · BR-8.1; DAP Backend spec · DAP-15
A32: C-6.5.4 | B32: I Conformance | C32: 6.5 The Ledger | D32: Metered event written before the result returns; if unwritable, no result | E32: DAP-21; DAP-29 | F32: V3 + V5 | G32: A result returned with no prior event under injected write failure | H32: DAP Backend spec · DAP-21; DAP Backend spec · DAP-29
A33: C-6.5.5 | B33: I Conformance | C33: 6.5 The Ledger | D33: Verifier runs under credentials the writer does not hold; writes to its own append-only store; publishes head hash to the tenant endpoint | E33: B-M10-Q2 ruling; C3 principle | F33: V2 + V3 | G33: A shared credential; verifier receipts inside the Ledger it verifies | I33: C3 — no registry row
A34: C-6.5.6 | B34: I Conformance | C34: 6.5 The Ledger | D34: Chain break raises SEV-1 and records a Watch signal, never an action | E34: B-M10-Q2 ruling | F34: V5 | G34: A break that neither pages nor signals; a break that triggers an action
A35: C-6.5.7 | B35: I Conformance | C35: 6.5 The Ledger | D35: au_3b_defensible coupled to at.source == reliable; False until a reliable time source exists | E35: R-C2; B-M10-Q1 | F35: V1 | G35: A record marked defensible with no reliable time source
A36: C-6.6.1 | B36: I Conformance | C36: 6.6 The Rules Service | D36: No rule takes effect without proposal, impact record, countersign, countdown, apply, re-verify | E36: RBM-7, RBM-8 | F36: V4 | G36: A rule in force with an incomplete ceremony record | H36: Rules Service spec · RBM-7; Rules Service spec · RBM-8
A37: C-6.6.2 | B37: I Conformance | C37: 6.6 The Rules Service | D37: Countdown cannot be shortened; Watch and Slow tiers cannot be applied by one principal, including under break-glass | E37: RBM-8; SER C.5 I-4 | F37: V5 | G37: A countdown cut short; a TCB-tier rule applied on one signature | H37: Rules Service spec · RBM-8
A38: C-6.6.3 | B38: I Conformance | C38: 6.6 The Rules Service | D38: Slowest tier requires a witness holding no credential over the component changed | E38: Doc 3 C3; R-16 | F38: V4 | G38: A witness who is also an operator of the changed component | I38: Doc 3 C3 — no registry row
A39: C-6.6.4 | B39: I Conformance | C39: 6.6 The Rules Service | D39: Every rule carries an ROC-compliant identifier and class | E39: ROC-1 to ROC-11 | F39: V7 | G39: A rule with a positional-only ID outside its document scope | H39: ROC spec · ROC-1; ROC spec · ROC-2; ROC spec · ROC-3; ROC spec · ROC-4; ROC spec · ROC-5; ROC spec · ROC-6; ROC spec · ROC-7; ROC spec · ROC-8; ROC spec · ROC-9; ROC spec · ROC-10; ROC spec · ROC-11
A40: C-6.6.5 | B40: I Conformance | C40: 6.6 The Rules Service | D40: Fallback-era determinations carry controlled_determination_basis and the flag cannot be flipped | E40: R-C1 | F40: V1 | G40: A fallback determination without the marker, or the marker mutable
...

Sheet Registry Defects
A1: Ref | B1: Artefact | C1: Defect observed at issue of v2 | D1: Measure | E1: Effect on the audit if left | F1: Owner action | G1: State
A2: RD-01 | B2: Master Registry · Status | C2: 349 of 602 rules are PROPOSED or DEFAULT, including every rule prefixed DAP, ENT, CON, PRIN, MEM, AC, RBM, BR, SEC, SFP, FP, TD, DET and I. Of the 89 registry rules Standards v1 §6 names, 2 are CANON or RULED (Doc 1 A5.1, Doc 1 A5.7). | D2: CANON 142 · RULED 16 · PROPOSED/DEFAULT 349 · OPEN 25 · outside vocabulary 70 | E2: Under v1 the domain passes §6.2 and §6.5–§6.14 could return only NOT YET RATIFIED. Either the Status column is stale or the newest work is unratified; the registry cannot say which. | F2: Confirm the Status column against DECISIONS.md before the audit target is tagged. v2 removes the dependency: every rule is examined and given a verdict whatever its status; status sets weight only. | G2: OPEN
A3: RD-02 | B3: Master Registry · Status | C3: 70 rows carry a status outside the vocabulary: “—” 27 (14 of them Doc 3, the Watch), “See xlsx” 25, “OWNER-DIRECTED → CANON” 14, “— (see heading)” 3, “DETERMINED” 1. | D3: 70 rows | E3: Weight cannot be set. Promise #6 rests on 14 such rows and nothing else. | F3: Rule each in the Status Map sheet, columns B and C. | G3: OPEN
A4: RD-03 | B4: Master Registry · Statement and class | C4: For all 232 rows from Docs 1–20 the Statement column holds the rule’s heading (Legend sheet says so). The v1 verification class was derived from that heading. All 158 CANON and RULED rules are heading-only; 139 of them fell to V7, document inspection. | D4: 232 heading-only · 158 COUNTS · 139 of those V7 | E4: The ratified core would be audited by reading documents. “The single chokepoint” is V7 in the sheet and V2 in Standards §6.3. | F4: Transcribe full rule text into the registry, or accept Standards 2.4: the auditor reads the text at Source file:line and re-derives the class. Column Q marks every provisional class. | G4: OPEN
A5: RD-04 | B5: Master Registry vs Standards §6 | C5: Of 89 rules named in §6, 48 carry a sheet class that is not among the classes §6 requires for them. | D5: 48 of 89 | E5: The auditor is told two different evidence standards for the same rule. | F5: Closed in v2: column O carries the §6 class and governs (class precedence, QA Legend). | G5: CLOSED
A6: RD-05 | B6: Standards v1 §6 · citations | C6: Standards cited as governing do not resolve to a registry row: Doc 0 BA-1.1, Doc 3 A2, Doc 3 A3, Doc 3 C3, B.4, B.8, D-14, LIM-3, DAP-31+, DAP-32+. | D6: 10 identifiers | E6: A check with no locatable rule cannot be verified against canon. | F6: Register the rules, or correct the citations. Check Register column I lists them per check. | G6: OPEN
A7: RD-06 | B7: Standards v1 §6.2 · citation | C7: The golden-input check cites DET-1 and DET-2. In the registry DET-1 is an OPEN item on a CIF halt mechanism and DET-2 concerns a Mtafiti classification step. | D7: 2 identifiers | E7: The TCB determinism check points at rules that say something else. | F7: Supply the correct identifiers. Until then C-6.2.2 is verified against tcb_enumeration_v1 and the determinism inventory text. | G7: OPEN
A8: RD-07 | B8: Promise Registry · security promises | C8: The 33 security assurance promises have no fulfilling-rule column. The text of S-1 to S-25 sits in Security_Assurance_Promise_Set.xlsx, which was not issued with the registries. | D8: 33 promises · 25 without text | E8: Promise roll-up cannot be computed for any security promise. | F8: Issue the workbook (Standards 9.1) and confirm the mapping proposed in Promise Registry v2, sheet Promise–Rule Map, which is drawn only from identifiers the promise rows themselves name. | G8: OPEN
A9: RD-08 | B9: Promise Registry · canon promises | C9: Promises #6, #25 and #26 have no CANON or RULED fulfilling rule. Promises #5, #28 and #29 have no rule at all (the Objectives sheet explains #5 and #29 as composite theorems of Doc 16; #28 is unexplained). | D9: 6 of 32 | E9: Under v1 these were vacuously HELD or undefined. | F9: v2 verdicts NO COUNTABLE RULES and ABSENT. Owner to explain #28. | G9: OPEN
A10: RD-09 | B10: Master Registry · sampling tier | C10: 110 of the 158 CANON and RULED rules were Tier B, sampled at 30%, while a promise is HELD only if every one passes. | D10: 110 of 158 | E10: A promise could be declared HELD on a third of its rules. | F10: Closed in v2: column R places every COUNTS rule in Tier A. | G10: CLOSED
A11: RD-10 | B11: Counts across artefacts | C11: Standards v1 states 595 rules and 299 Tier A; the registry holds 602 and 306; Build Status totals 589; the Legend sheet says 286 and says the S-series and RBM rules are not included, though both are. | D11: 595 / 602 / 589 / 286 | E11: The auditor cannot confirm it holds the version the Standards describe. | F11: Refresh Build Status and Legend. v2 pins the registry by hash in the Audit Order. | G11: OPEN
A12: RD-11 | B12: Master Registry · Build Status | C12: Sections 2–4 list as missing documents the registry carries rows from: security_architecture_v1, determinism_inventory_v1, failure_posture_v1, trust_domains_v1, handoff_registry_v1, business_continuity_v1. | D12: 6 documents | E12: The builder’s own status sheet contradicts the registry it ships in. | F12: Refresh Build Status, or mark it superseded. | G12: OPEN
... A17: RD-16 | B17: Master Registry · extraction damage | C17: Two Deck Engine statements are fragments: DR-R10 “–R11)” and DR-R13 “)”. | D17: 2 rows | E17: The rules cannot be read. | F17: Re-extract. | G17: OPEN

Sheet QA Legend
A1: Class | B1: Name | C1: Evidence standard | D1: Derivation pattern (first match, in this order)
